<?xml version="1.0" ?>
<!-- =================================================================================== -->
<!-- |    This document was autogenerated by xacro from dummy_bot.xacro                | -->
<!-- |    EDITING THIS FILE BY HAND IS NOT RECOMMENDED                                 | -->
<!-- =================================================================================== -->
<robot name="bot">
  <gazebo reference="camera_link">
    <sensor name="camera1" type="camera">
      <update_rate>30.0</update_rate>
      <camera name="head">
        <horizontal_fov>1.765994316</horizontal_fov>
        <intrinsics>
          <fx>525.879333496</fx>
          <fy>525.879333496</fy>
          <cx>651.249389648</cx>
          <cy>350.848449707</cy>
        </intrinsics>
        <image>
          <width>800</width>
          <height>800</height>
          <format>R8G8B8</format>
        </image>
        <clip>
          <near>0.02</near>
          <far>300</far>
        </clip>
        <noise>
          <type>gaussian</type>
          <mean>0.0</mean>
          <stddev>0.007</stddev>
        </noise>
      </camera>
      <plugin filename="libgazebo_ros_camera.so" name="camera_controller">
        <alwaysOn>true</alwaysOn>
        <updateRate>0.0</updateRate>
        <cameraName>robot/camera1</cameraName>
        <imageTopicName>image</imageTopicName>
        <cameraInfoTopicName>camera_info</cameraInfoTopicName>
        <frameName>camera_frame</frameName>
        <hackBaseline>0.07</hackBaseline>
        <distortionK1>0.0</distortionK1>
        <distortionK2>0.0</distortionK2>
        <distortionK3>0.0</distortionK3>
        <distortionT1>0.0</distortionT1>
        <distortionT2>0.0</distortionT2>
      </plugin>
    </sensor>
  </gazebo>
  <gazebo reference="camera_short_link">
    <sensor name="short_1_camera" type="camera">
      <update_rate>30.0</update_rate>
      <camera name="head">
        <horizontal_fov>1.72998742</horizontal_fov>
        <intrinsics>
          <fx>545.444152832</fx>
          <fy>545.444152832</fy>
          <cx>641.510314941</cx>
          <cy>350.597442626</cy>
        </intrinsics>
        <image>
          <width>800</width>
          <height>800</height>
          <format>R8G8B8</format>
        </image>
        <clip>
          <near>0.02</near>
          <far>300</far>
        </clip>
        <noise>
          <type>gaussian</type>
          <mean>0.0</mean>
          <stddev>0.007</stddev>
        </noise>
      </camera>
      <plugin filename="libgazebo_ros_camera.so" name="camera_short_controller">
        <alwaysOn>true</alwaysOn>
        <updateRate>0.0</updateRate>
        <cameraName>robot/camera_short_1</cameraName>
        <imageTopicName>image</imageTopicName>
        <cameraInfoTopicName>camera_info</cameraInfoTopicName>
        <frameName>camera_short_frame</frameName>
        <hackBaseline>0.07</hackBaseline>
        <distortionK1>0.0</distortionK1>
        <distortionK2>0.0</distortionK2>
        <distortionK3>0.0</distortionK3>
        <distortionT1>0.0</distortionT1>
        <distortionT2>0.0</distortionT2>
      </plugin>
    </sensor>
  </gazebo>
  <gazebo reference="lidar_link">
    <sensor name="lidar" type="gpu_ray">
      <pose>0 0 0 0 0 0</pose>
      <visualize>true</visualize>
      <update_rate>40</update_rate>
      <ray>
        <scan>
          <horizontal>
            <samples>720</samples>
            <resolution>1</resolution>
            <min_angle>-3.14</min_angle>
            <max_angle>0</max_angle>
          </horizontal>
        </scan>
        <range>
          <min>0.10</min>
          <max>20.0</max>
          <resolution>0.01</resolution>
        </range>
        <noise>
          <type>gaussian</type>
          <!-- Noise parameters based on published spec for Hokuyo laser
               achieving "+-30mm" accuracy at range < 10m.  A mean of 0.0m and
               stddev of 0.01m will put 99.7% of samples within 0.03m of the true
               reading. -->
          <mean>0.0</mean>
          <stddev>0.01</stddev>
        </noise>
      </ray>
      <plugin filename="libgazebo_ros_ray_sensor.so" name="bytes_laserscan">
        <ros>
          <namespace>lidar</namespace>
          <remapping>~/out:=scan</remapping>
        </ros>
        <output_type>sensor_msgs/LaserScan</output_type>
        <frame_name>lidar_link</frame_name>
      </plugin>
    </sensor>
  </gazebo>
  <gazebo reference="gps_link">
    <sensor name="bot_gps" type="gps">
      <always_on>true</always_on>
      <update_rate>1</update_rate>
      <pose>0 0 0 0 0 0</pose>
      <gps>
        <position_sensing>
          <horizontal>
            <noise type="gaussian">
              <mean>0.0</mean>
              <stddev>0.01</stddev>
            </noise>
          </horizontal>
          <vertical>
            <noise type="gaussian">
              <mean>0.0</mean>
              <stddev>0.01</stddev>
            </noise>
          </vertical>
        </position_sensing>
      </gps>
      <plugin filename="libgazebo_ros_gps_sensor.so" name="my_gps_plugin">
        <ros>
          <namespace>gps</namespace>
          <remapping>~/out:=fix</remapping>
        </ros>
        <output_type>sensor_msgs/NavSatFix</output_type>
        <frame_name>gps_link</frame_name>
      </plugin>
    </sensor>
  </gazebo>
  <material name="white">
    <color rgba="1 1 1 1"/>
  </material>
  <material name="orange">
    <color rgba="1 0.3 0.1 1"/>
  </material>
  <material name="blue">
    <color rgba="0.2 0.2 1 1"/>
  </material>
  <material name="black">
    <color rgba="0 0 0 1"/>
  </material>
  <link name="base_link">
    <inertial>
      <origin rpy="0 0 0" xyz="0 0 0"/>
      <mass value="1"/>
      <inertia ixx="1.3" ixy="0.0" ixz="0.0" iyy="1.3" iyz="0.0" izz="1.3"/>
    </inertial>
  </link>
  <joint name="chassis_joint" type="fixed">
    <parent link="base_link"/>
    <child link="chassis"/>
    <origin xyz="-0.1 0 0"/>
  </joint>
  <link name="chassis">
    <visual>
      <origin rpy="0 0 0" xyz="0.15 0 0.075"/>
      <geometry>
        <box size="0.3 0.3 0.15"/>
      </geometry>
      <material name="white"/>
    </visual>
  </link>
  <!-- LEFT WHEEL -->
  <joint name="left_wheel_joint" type="continuous">
    <parent link="base_link"/>
    <child link="left_wheel"/>
    <origin rpy="-1.5707963267948966 0 0" xyz="0 0.175 0"/>
    <axis xyz="0 0 1"/>
  </joint>
  <link name="left_wheel">
    <visual>
      <geometry>
        <cylinder length="0.04" radius="0.05"/>
      </geometry>
    </visual>
  </link>
  <!-- RIGHT WHEEL -->
  <joint name="right_wheel_joint" type="continuous">
    <parent link="base_link"/>
    <child link="right_wheel"/>
    <origin rpy="1.5707963267948966 0 0" xyz="0 -0.175 0"/>
    <axis xyz="0 0 -1"/>
  </joint>
  <link name="right_wheel">
    <visual>
      <geometry>
        <cylinder length="0.04" radius="0.05"/>
      </geometry>
    </visual>
  </link>
  <link name="caster_part">
    <collision>
      <origin rpy="0 0 -1.57" xyz="0 0 0"/>
      <geometry>
        <mesh filename="package://robot_desc/meshes/caster_base2.dae" scale="2 2 2"/>
      </geometry>
    </collision>
    <visual>
      <origin rpy="0 0 -1.57" xyz="0 0 0"/>
      <geometry>
        <mesh filename="package://robot_desc/meshes/caster_base2.dae" scale="2 2 2"/>
      </geometry>
    </visual>
    <inertial>
      <origin rpy="0 0 -1.57" xyz="0 0 0"/>
      <mass value="0.5"/>
      <inertia ixx="0.000625" ixy="0.0" ixz="0.0" iyy="0.0003125" iyz="0.0" izz="0.0003125"/>
    </inertial>
  </link>
  <link name="caster_wheel">
    <collision>
      <origin rpy="0 1.57 0" xyz="0 0 0"/>
      <geometry>
        <mesh filename="package://robot_desc/meshes/caswheel.dae" scale="2 2 2"/>
      </geometry>
    </collision>
    <visual>
      <origin rpy="0 1.57 0" xyz="0 0 0"/>
      <geometry>
        <mesh filename="package://robot_desc/meshes/caswheel.dae" scale="2 2 2"/>
      </geometry>
    </visual>
    <inertial>
      <origin rpy="0 1.57 0" xyz="0 0 0"/>
      <mass value="0.5"/>
      <inertia ixx="0.000625" ixy="0.0" ixz="0.0" iyy="0.0003125" iyz="0.0" izz="0.0003125"/>
    </inertial>
  </link>
  <joint name="caster_joint" type="continuous">
    <parent link="caster_part"/>
    <child link="caster_wheel"/>
    <origin rpy="0 0 0" xyz="0 0.05 -0.086"/>
    <limit effort="1000000" velocity="10000000"/>
  </joint>
  <joint name="caster_body_joint" type="continuous">
    <parent link="chassis"/>
    <child link="caster_part"/>
    <origin rpy="0 0 0" xyz="0.24 0 0"/>
    <axis xyz="0 0 1"/>
    <limit effort="1000000" velocity="10000000"/>
  </joint>
  <link name="camera_short_link">
    <collision>
      <origin rpy="0 0 0" xyz="0 0 0"/>
      <geometry>
        <box size="0.001 0.001 0.001"/>
      </geometry>
    </collision>
    <visual>
      <origin rpy="0 0 0" xyz="0 0 0"/>
      <geometry>
        <box size="0.001 0.001 0.001"/>
      </geometry>
    </visual>
    <inertial>
      <origin rpy="0 0 0" xyz="0 0 0"/>
      <mass value="0.5"/>
      <inertia ixx="0.00000625" ixy="0.0" ixz="0.0" iyy="0.000003125" iyz="0.0" izz="0.000003125"/>
    </inertial>
  </link>
  <joint name="camera_short_joint" type="fixed">
    <parent link="chassis"/>
    <child link="camera_short_link"/>
    <origin rpy="0 0 -2.355" xyz="-0.021204755433160978 -0.203778351924984 0.9"/>
    <axis xyz="0 0 1"/>
    <limit effort="1000000" velocity="1000000"/>
  </joint>
  <link name="camera_link">
    <collision>
      <origin rpy="0 0 0" xyz="0 0 0"/>
      <geometry>
        <box size="0.001 0.001 0.001"/>
      </geometry>
    </collision>
    <visual>
      <origin rpy="0 0 0" xyz="0 0 0"/>
      <geometry>
        <box size="0.001 0.001 0.001"/>
      </geometry>
    </visual>
    <inertial>
      <origin rpy="0 0 0" xyz="0 0 0"/>
      <mass value="0.5"/>
      <inertia ixx="0.00000625" ixy="0.0" ixz="0.0" iyy="0.000003125" iyz="0.0" izz="0.000003125"/>
    </inertial>
  </link>
  <joint name="camera_joint" type="fixed">
    <parent link="chassis"/>
    <child link="camera_link"/>
    <origin rpy="0 0 -0.785" xyz="0.021204755433160978 -0.203778351924984 0.9"/>
    <axis xyz="0 0 1"/>
    <limit effort="1000000" velocity="1000000"/>
  </joint>
  <link name="lidar_link">
    <collision>
      <origin rpy="0 0 0" xyz="0 0 0"/>
      <geometry>
        <box size="0.001 0.001 0.001"/>
      </geometry>
    </collision>
    <visual>
      <origin rpy="0 0 0" xyz="0 0 0"/>
      <geometry>
        <box size="0.001 0.001 0.001"/>
      </geometry>
    </visual>
    <inertial>
      <mass value="1e-5"/>
      <origin rpy="0 0 0" xyz="0 0 0"/>
      <inertia ixx="1e-6" ixy="0" ixz="0" iyy="1e-6" iyz="0" izz="1e-6"/>
    </inertial>
  </link>
  <joint name="lidar_joint" type="fixed">
    <parent link="chassis"/>
    <child link="lidar_link"/>
    <origin rpy="0 0 0" xyz="0 -0.1125 0.45"/>
  </joint>
  <link name="gps_link">
    <collision>
      <origin rpy="0 0 0" xyz="0 0 0"/>
      <geometry>
        <box size="0.001 0.001 0.001"/>
      </geometry>
    </collision>
    <visual>
      <origin rpy="0 0 0" xyz="0 0 0"/>
      <geometry>
        <box size="0.001 0.001 0.001"/>
      </geometry>
    </visual>
    <inertial>
      <mass value="1e-5"/>
      <origin rpy="0 0 0" xyz="0 0 0"/>
      <inertia ixx="1e-6" ixy="0" ixz="0" iyy="1e-6" iyz="0" izz="1e-6"/>
    </inertial>
  </link>
  <joint name="gps_joint" type="fixed">
    <parent link="chassis"/>
    <child link="gps_link"/>
    <origin rpy="0 0 0" xyz="0 0 0"/>
  </joint>
</robot>
